Workbook
Name corr: 'T21.3.1'!#REF!
Name data: #REF!

Sheet T21.3.1
A1: Regionalporträts 2021: Gemeinden - Kennzahlen | AQ1: T21.3.1
C4: Bevölkerung | G4: Altersverteilung in % | J4: Bevölkerungsbewegung (in ‰) | N4: Haushalte | P4: Fläche | W4: Wirtschaft | AE4: Bau- und Wohnungswesen | AG4: Soziale Sicherheit | AH4: Wähleranteile ausgewählter Parteien in % (Nationalratswahlen)
A6: Gemeindecode | B6: Gemeindename | C6: Einwohner | D6: Veränderung in % | E6: Bevölkerungs-dichte pro km² | F6: Ausländer in % | G6: 0-19 Jahre | H6: 20-64 Jahre | I6: 65 Jahre und mehr | J6: Rohe Heiratssziffer | K6: Rohe Scheidungsziffer | L6: Rohe Geburtenziffer | M6: Rohe Sterbeziffer | N6: Anzahl Privathaushalte | O6: Durchschnittliche Haushaltsgrösse in Personen | P6: Gesamtfläche in km² 1) | Q6: Siedlungsfläche in % | R6: Veränderung in ha | S6: Landwirtschafts-fläche in % | T6: Veränderung in ha | U6: Wald und Gehölze in % | V6: Unproduktive Fläche in % | W6: Beschäftigte total | X6: im 1. Sektor | Y6: im 2. Sektor | Z6: im 3. Sektor | AA6: Arbeitsstätten total | AB6: im 1. Sektor | AC6: im 2. Sektor | AD6: im 3. Sektor | AE6: Leerwohnungs-ziffer | AF6: Neu gebaute Wohnungen pro 1000 Einwohner | AG6: Sozialhilfequote | AH6: FDP 2) | AI6: CVP | AJ6: SP | AK6: SVP | AL6: EVP/CSP | AM6: GLP | AN6: BDP | AO6: PdA/Sol. | AP6: GPS | AQ6: Kleine Rechtsparteien
C7: 2019 | D7: 2010-2019 | E7: 2019 | F7: 2019 | G7: 2019 | H7: 2019 | I7: 2019 | J7: 2019 | K7: 2019 | L7: 2019 | M7: 2019 | N7: 2019 | O7: 2019 | P7: 2016 | Q7: 2004/09 | R7: 1979/85-2004/09 | S7: 2004/09 | T7: 1979/85-2004/09 | U7: 2004/09 | V7: 2004/09 | W7: 2018 | X7: 2018 | Y7: 2018 | Z7: 2018 | AA7: 2018 | AB7: 2018 | AC7: 2018 | AD7: 2018 | AE7: 2020 | AF7: 2018 | AG7: 2019 | AH7: 2019 | AI7: 2019 | AJ7: 2019 | AK7: 2019 | AL7: 2019 | AM7: 2019 | AN7: 2019 | AO7: 2019 | AP7: 2019 | AQ7: 2019
B9: Schweiz | C9: 8606033 | D9: 9.4 | E9: 215.2 | F9: 25.3 | G9: 20 | H9: 61.4 | I9: 18.7 | J9: 4.5 | K9: 2 | L9: 10 | M9: 7.9 | N9: 3811306 | O9: 2.21 | P9: 41290.76 | Q9: 7.5 | R9: 58409 | S9: 35.9 | T9: -85056 | U9: 31.3 | V9: 25.3 | W9: 5249958 | X9: 161497 | Y9: 1091626 | Z9: 3996835 | AA9: 687022 | AB9: 53457 | AC9: 95687 | AD9: 537878 | AE9: 1.72 | AF9: 6.3 | AG9: 3.2 | AH9: 15.1 | AI9: 11.4 | AJ9: 16.8 | AK9: 25.6 | AL9: 2.3 | AM9: 7.8 | AN9: 2.4 | AO9: 1 | AP9: 13.2 | AQ9: 2.1
A10: 1 | B10: Aeugst am Albis | C10: 1981 | D10: 8.6074561 | E10: 250.44248 | F10: 14.184755 | G10: 19.787986 | H10: 62.190813 | I10: 18.021201 | J10: 7.0653545 | K10: 2.0186727 | L10: 9.0840273 | M10: 6.5606863 | N10: 848 | O10: 2.3242925 | P10: 7.91 | Q10: 12.658228 | R10: 21 | S10: 51.139241 | T10: -22 | U10: 30.886076 | V10: 5.3164557 | W10: 442 | X10: 39 | Y10: 25 | Z10: 378 | AA10: 141 | AB10: 15 | AC10: 16 | AD10: 110 | AE10: 5.2915767 | AF10: 13.910355 | AG10: 1.01 | AH10: 16.421045 | AI10: 2.4979736 | AJ10: 11.565102 | AK10: 30.380959 | AL10: 3.2274703 | AM10: 14.317294 | AN10: 1.2637241 | AO10: 0.16211038 | AP10: 15.050475 | AQ10: 3.820647
A11: 2 | B11: Affoltern am Albis | C11: 12303 | D11: 10.927779 | E11: 1161.7564 | F11: 28.700317 | G11: 20.165813 | H11: 61.667886 | I11: 18.166301 | J11: 5.5437796 | K11: 1.7935757 | L11: 12.881135 | M11: 9.2124572 | N11: 5412 | O11: 2.2259793 | P11: 10.59 | Q11: 30.674264 | R11: 92 | S11: 40.17094 | T11: -93 | U11: 28.205128 | V11: 0.94966762 | W11: 6920 | X11: 47 | Y11: 1307 | Z11: 5566 | AA11: 995 | AB11: 23 | AC11: 134 | AD11: 838 | AE11: 1.0055479 | AF11: 3.7872551 | AG11: 3.02 | AH11: 13.385437 | AI11: 4.5353414 | AJ11: 14.645255 | AK11: 30.30692 | AL11: 6.6185559 | AM11: 12.666629 | AN11: 2.0014452 | AO11: 0.19871831 | AP11: 12.590564 | AQ11: 1.5555175
A12: 3 | B12: Bonstetten | C12: 5572 | D12: 8.0054274 | E12: 749.93271 | F12: 16.564968 | G12: 23.636037 | H12: 59.834889 | I12: 16.529074 | J12: 4.3165468 | K12: 1.7985612 | L12: 9.8920863 | M12: 4.3165468 | N12: 2327 | O12: 2.3841856 | P12: 7.43 | Q12: 15.456989 | R12: 24 | S12: 55.510753 | T12: -21 | U12: 28.629032 | V12: 0.40322581 | W12: 1014 | X12: 34 | Y12: 111 | Z12: 869 | AA12: 281 | AB12: 14 | AC12: 26 | AD12: 241 | AE12: 1.1717172 | AF12: 0.18142235 | AG12: 1.51 | AH12: 15.354984 | AI12: 3.8679613 | AJ12: 16.742891 | AK12: 26.116313 | AL12: 4.1940184 | AM12: 16.237935 | AN12: 1.2840304 | AO12: 0.17601316 | AP12: 12.368531 | AQ12: 1.3850216
A13: 4 | B13: Hausen am Albis | C13: 3751 | D13: 11.636905 | E13: 275.80882 | F13: 16.022394 | G13: 22.180752 | H13: 59.824047 | I13: 17.995201 | J13: 3.2206119 | K13: 1.610306 | L13: 8.5882984 | M13: 3.7573806 | N13: 1552 | O13: 2.4007732 | P13: 13.6 | Q13: 12.69259 | R13: 33 | S13: 55.90609 | T13: -31 | U13: 28.833456 | V13: 2.567865 | W13: 1021 | X13: 93 | Y13: 136 | Z13: 792 | AA13: 271 | AB13: 36 | AC13: 38 | AD13: 197 | AE13: 0.63001145 | AF13: 3.0021834 | AG13: 1.19 | AH13: 11.135163 | AI13: 3.9345515 | AJ13: 13.711509 | AK13: 33.18478 | AL13: 4.059761 | AM13: 12.416969 | AN13: 1.6107468 | AO13: 0.19311984 | AP13: 16.744127 | AQ13: 1.6107468
A14: 5 | B14: Hedingen | C14: 3778 | D14: 10.791789 | E14: 578.56049 | F14: 16.410799 | G14: 21.625199 | H14: 61.646374 | I14: 16.728428 | J14: 3.7273695 | K14: 2.1299255 | L14: 7.4547391 | M14: 6.3897764 | N14: 1580 | O14: 2.378481 | P14: 6.53 | Q14: 19.817073 | R14: 44 | S14: 46.341463 | T14: -43 | U14: 33.231707 | V14: 0.6097561 | W14: 1478 | X14: 29 | Y14: 679 | Z14: 770 | AA14: 201 | AB14: 11 | AC14: 26 | AD14: 164 | AE14: 0.96269555 | AF14: 3.2485111 | AG14: 1.47 | AH14: 13.990898 | AI14: 3.8736604 | AJ14: 16.738323 | AK14: 26.601791 | AL14: 3.7268514 | AM14: 16.415344 | AN14: 1.8812525 | AO14: 0.18246262 | AP14: 12.348734 | AQ14: 2.170676
A15: 6 | B15: Kappel am Albis | C15: 1221 | D15: 33.006536 | E15: 154.16667 | F15: 17.526618 | G15: 24.979525 | H15: 61.179361 | I15: 13.841114 | J15: 3.3641716 | K15: 0 | L15: 10.092515 | M15: 5.0462574 | N15: 493 | O15: 2.4665314 | P15: 7.92 | Q15: 8.3120205 | R15: 12 | S15: 69.948849 | T15: -12 | U15: 20.588235 | V15: 1.1508951 | W15: 319 | X15: 56 | Y15: 81 | Z15: 182 | AA15: 101 | AB15: 21 | AC15: 24 | AD15: 56 | AE15: 2.1778584 | AF15: 37.333333 | AG15: 0.69 | AH15: 10.86289 | AI15: 5.4966989 | AJ15: 9.0741594 | AK15: 43.635805 | AL15: 4.5140488 | AM15: 10.870567 | AN15: 1.2666974 | AO15: 0.046061723 | AP15: 10.179641 | AQ15: 1.6275142
A16: 7 | B16: Knonau | C16: 2378 | D16: 32.111111 | E16: 367.5425 | F16: 18.292683 | G16: 24.348192 | H16: 60.97561 | I16: 14.676198 | J16: 3.3677121 | K16: 0.84192802 | L16: 12.62892 | M16: 8.4192802 | N16: 927 | O16: 2.5587918 | P16: 6.47 | Q16: 18.027735 | R16: 19 | S16: 62.249615 | T16: -21 | U16: 17.103236 | V16: 2.6194145 | W16: 566 | X16: 55 | Y16: 108 | Z16: 403 | AA16: 133 | AB16: 24 | AC16: 15 | AD16: 94 | AE16: 0.58823529 | AF16: 5.6399132 | AG16: 0.84 | AH16: 9.2047953 | AI16: 5.3428465 | AJ16: 11.432364 | AK16: 32.268636 | AL16: 6.9067076 | AM16: 17.322769 | AN16: 2.6672751 | AO16: 0.095407973 | AP16: 11.349401 | AQ16: 2.2026797
A17: 8 | B17: Maschwanden | C17: 645 | D17: 4.7077922 | E17: 137.52665 | F17: 12.868217 | G17: 22.015504 | H17: 59.534884 | I17: 18.449612 | J17: 3.074558 | K17: 0 | L17: 6.1491161 | M17: 7.6863951 | N17: 274 | O17: 2.3540146 | P17: 4.69 | Q17: 8.974359 | R17: -5 | S17: 59.615385 | T17: 0 | U17: 23.717949 | V17: 7.6923077 | W17: 175 | X17: 49 | Y17: 49 | Z17: 77 | AA17: 67 | AB17: 18 | AC17: 7 | AD17: 42 | AE17: 2.9900332 | AF17: 0 | AG17: X | AH17: 3.3391916 | AI17: 2.5550899 | AJ17: 16.9393 | AK17: 44.518048 | AL17: 3.4067865 | AM17: 12.288766 | AN17: 2.9336217 | AO17: 0.067594971 | AP17: 10.017575 | AQ17: 2.9876977
A18: 9 | B18: Mettmenstetten | C18: 5200 | D18: 22.554796 | E18: 399.07905 | F18: 14.769231 | G18: 23.096154 | H18: 59.211538 | I18: 17.692308 | J18: 5.0514863 | K18: 2.3314552 | L18: 13.794443 | M18: 4.6629104 | N18: 2097 | O18: 2.4492132 | P18: 13.03 | Q18: 15.990819 | R18: 65 | S18: 64.269319 | T18: -70 | U18: 18.592196 | V18: 1.1476664 | W18: 1680 | X18: 148 | Y18: 545 | Z18: 987 | AA18: 319 | AB18: 51 | AC18: 58 | AD18: 210 | AE18: 1.3250883 | AF18: 18.215309 | AG18: 1.61 | AH18: 11.823788 | AI18: 3.5628405 | AJ18: 15.37027 | AK18: 31.229654 | AL18: 4.6572116 | AM18: 14.648869 | AN18: 1.3577399 | AO18: 0.38769201 | AP18: 11.825424 | AQ18: 3.9292667
A19: 10 | B19: Obfelden | C19: 5721 | D19: 22.087068 | E19: 758.75332 | F19: 21.464779 | G19: 23.579794 | H19: 59.639923 | I19: 16.780283 | J19: 4.9469965 | K19: 1.9434629 | L19: 12.190813 | M19: 6.0070671 | N19: 2341 | O19: 2.4246049 | P19: 7.54 | Q19: 24.338624 | R19: 46 | S19: 49.074074 | T19: -44 | U19: 21.428571 | V19: 5.1587302 | W19: 1252 | X19: 51 | Y19: 310 | Z19: 891 | AA19: 307 | AB19: 17 | AC19: 60 | AD19: 230 | AE19: 2.1454112 | AF19: 7.2815534 | AG19: 2.57 | AH19: 11.511818 | AI19: 6.3924942 | AJ19: 14.642409 | AK19: 33.715221 | AL19: 5.3248582 | AM19: 14.560575 | AN19: 1.8421954 | AO19: 0.085639249 | AP19: 8.5487002 | AQ19: 2.1733338
A20: 11 | B20: Ottenbach | C20: 2588 | D20: 7.3858921 | E20: 515.53785 | F20: 13.137558 | G20: 20.170015 | H20: 58.462133 | I20: 21.367852 | J20: 5.0554151 | K20: 3.1110247 | L20: 7.3886836 | M20: 6.6109275 | N20: 1128 | O20: 2.2810284 | P20: 5.02 | Q20: 20.758483 | R20: 20 | S20: 54.690619 | T20: -19 | U20: 20.359281 | V20: 4.1916168 | W20: 683 | X20: 38 | Y20: 237 | Z20: 408 | AA20: 175 | AB20: 14 | AC20: 33 | AD20: 128 | AE20: 1.1363636 | AF20: 7.7851304 | AG20: 1.1 | AH20: 13.145065 | AI20: 3.5642093 | AJ20: 13.650416 | AK20: 32.30975 | AL20: 3.9476813 | AM20: 16.840071 | AN20: 2.9399524 | AO20: 0.23483948 | AP20: 10.707491 | AQ20: 1.8103448
A21: 12 | B21: Rifferswil | C21: 1129 | D21: 25.444444 | E21: 173.4255 | F21: 10.717449 | G21: 27.103632 | H21: 56.244464 | I21: 16.651904 | J21: 2.6642984 | K21: 0.88809947 | L21: 7.1047957 | M21: 5.3285968 | N21: 456 | O21: 2.4583333 | P21: 6.51 | Q21: 10.334347 | R21: 10 | S21: 64.893617 | T21: -10 | U21: 22.644377 | V21: 2.1276596 | W21: 250 | X21: 42 | Y21: 72 | Z21: 136 | AA21: 87 | AB21: 17 | AC21: 16 | AD21: 54 | AE21: 1.1787819 | AF21: 0.90661831 | AG21: 0.62 | AH21: 6.859766 | AI21: 3.6141462 | AJ21: 14.792785 | AK21: 26.818388 | AL21: 7.0731234 | AM21: 12.698002 | AN21: 1.2413526 | AO21: 0.25861512 | AP21: 21.594362 | AQ21: 3.2650158
A22: 13 | B22: Stallikon | C22: 3755 | D22: 18.791522 | E22: 312.39601 | F22: 22.29028 | G22: 21.358189 | H22: 62.370173 | I22: 16.271638 | J22: 4.5729657 | K22: 0.80699395 | L22: 9.6839274 | M22: 6.7249496 | N22: 1554 | O22: 2.4086229 | P22: 12.02 | Q22: 11.064892 | R22: 45 | S22: 38.019967 | T22: -41 | U22: 49.833611 | V22: 1.0815308 | W22: 775 | X22: 38 | Y22: 155 | Z22: 582 | AA22: 189 | AB22: 15 | AC22: 25 | AD22: 149 | AE22: 1.1329756 | AF22: 0.53806833 | AG22: 1.14 | AH22: 14.674386 | AI22: 4.580622 | AJ22: 14.300354 | AK22: 35.617667 | AL22: 1.7574422 | AM22: 15.70682 | AN22: 0.98119588 | AO22: 0.099912896 | AP22: 10.631757 | AQ22: 0.21519701
A23: 14 | B23: Wettswil am Albis | C23: 5240 | D23: 15.980522 | E23: 1389.9204 | F23: 17.118321 | G23: 23.473282 | H23: 56.316794 | I23: 20.209924 | J23: 6.1373226 | K23: 1.9179133 | L23: 8.0552359 | M23: 5.3701573 | N23: 2163 | O23: 2.4012945 | P23: 3.77 | Q23: 41.066667 | R23: 55 | S23: 34.133333 | T23: -53 | U23: 20.533333 | V23: 4.2666667 | W23: 1302 | X23: 15 | Y23: 452 | Z23: 835 | AA23: 293 | AB23: 7 | AC23: 36 | AD23: 250 | AE23: 0.30905077 | AF23: 1.7605634 | AG23: 1.73 | AH23: 22.106586 | AI23: 4.6655497 | AJ23: 12.290566 | AK23: 28.379946 | AL23: 2.0089573 | AM23: 17.107553 | AN23: 1.6754736 | AO23: 0.098272973 | AP23: 9.2714912 | AQ23: 1.2179405
A24: 21 | B24: Adlikon | C24: 698 | D24: 20.970537 | E24: 106.07903 | F24: 10.601719 | G24: 21.203438 | H24: 60.028653 | I24: 18.767908 | J24: 7.1174377 | K24: 2.8469751 | L24: 9.9644128 | M24: 2.8469751 | N24: 274 | O24: 2.4854015 | P24: 6.58 | Q24: 10.876133 | R24: 10 | S24: 63.897281 | T24: -12 | U24: 22.65861 | V24: 2.5679758 | W24: 149 | X24: 49 | Y24: 24 | Z24: 76 | AA24: 65 | AB24: 22 | AC24: 6 | AD24: 37 | AE24: 0.33898305 | AF24: 21.052632 | AG24: X | AH24: 9.3611979 | AI24: 1.3250027 | AJ24: 6.0971669 | AK24: 56.458042 | AL24: 6.7111925 | AM24: 6.4095659 | AN24: 3.9103738 | AO24: 0 | AP24: 6.7650544 | AQ24: 2.8977701
A25: 22 | B25: Benken (ZH) | C25: 845 | D25: 5.8897243 | E25: 149.29329 | F25: 12.781065 | G25: 20.35503 | H25: 63.431953 | I25: 16.213018 | J25: 3.5294118 | K25: 0 | L25: 11.764706 | M25: 4.7058824 | N25: 362 | O25: 2.3176796 | P25: 5.66 | Q25: 8.1128748 | R25: 6 | S25: 57.495591 | T25: -9 | U25: 34.038801 | V25: 0.35273369 | W25: 249 | X25: 83 | Y25: 42 | Z25: 124 | AA25: 69 | AB25: 19 | AC25: 10 | AD25: 40 | AE25: 0.99750623 | AF25: 0 | AG25: 0.94 | AH25: 9.8324691 | AI25: 2.802154 | AJ25: 10.490626 | AK25: 46.649382 | AL25: 1.2066215 | AM25: 9.3338652 | AN25: 4.1882728 | AO25: 0.069804547 | AP25: 12.145991 | AQ25: 2.5727962
A26: 23 | B26: Berg am Irchel | C26: 577 | D26: -3.672788 | E26: 82.310984 | F26: 8.8388215 | G26: 14.211438 | H26: 61.69844 | I26: 24.090121 | J26: 5.2310375 | K26: 1.7436792 | L26: 8.7183958 | M26: 8.7183958 | N26: 257 | O26: 2.2256809 | P26: 7.01 | Q26: 4.9786629 | R26: 7 | S26: 48.079659 | T26: -10 | U26: 45.376956 | V26: 1.5647226 | W26: 137 | X26: 46 | Y26: 22 | Z26: 69 | AA26: 47 | AB26: 16 | AC26: 9 | AD26: 22 | AE26: 2.0408163 | AF26: 1.7730496 | AG26: 1.23 | AH26: 7.3331841 | AI26: 1.0747873 | AJ26: 6.1688312 | AK26: 52.70936 | AL26: 2.2391402 | AM26: 15.147783 | AN26: 3.5042544 | AO26: 0.45902373 | AP26: 8.083296 | AQ26: 2.8549037
A27: 24 | B27: Buch am Irchel | C27: 979 | D27: 12.788018 | E27: 95.886386 | F27: 7.2522983 | G27: 24.616956 | H27: 60.061287 | I27: 15.321757 | J27: 6.1349693 | K27: 1.0224949 | L27: 7.1574642 | M27: 5.1124744 | N27: 387 | O27: 2.5193798 | P27: 10.21 | Q27: 6.8897638 | R27: 9 | S27: 55.11811 | T27: -8 | U27: 37.992126 | V27: 0 | W27: 200 | X27: 72 | Y27: 38 | Z27: 90 | AA27: 74 | AB27: 24 | AC27: 7 | AD27: 43 | AE27: 1.1904762 | AF27: 3.0895984 | AG27: X | AH27: 13.150266 | AI27: 2.4561121 | AJ27: 4.8719601 | AK27: 48.631019 | AL27: 4.2357868 | AM27: 12.200032 | AN27: 3.1647608 | AO27: 0 | AP27: 6.4100499 | AQ27: 4.4612659
A28: 25 | B28: Dachsen | C28: 1916 | D28: -1.1861784 | E28: 709.62963 | F28: 13.308977 | G28: 21.085595 | H28: 58.037578 | I28: 20.876827 | J28: 3.1282586 | K28: 1.0427529 | L28: 7.2992701 | M28: 6.2565172 | N28: 789 | O28: 2.4169835 | P28: 2.7 | Q28: 32.075472 | R28: 17 | S28: 48.301887 | T28: -16 | U28: 12.45283 | V28: 7.1698113 | W28: 455 | X28: 18 | Y28: 159 | Z28: 278 | AA28: 104 | AB28: 6 | AC28: 25 | AD28: 73 | AE28: 2.4361949 | AF28: 1.5495868 | AG28: 0.63 | AH28: 10.465391 | AI28: 5.0413418 | AJ28: 15.095677 | AK28: 30.318923 | AL28: 3.935743 | AM28: 12.804158 | AN28: 2.0458304 | AO28: 0.10394519 | AP28: 17.127333 | AQ28: 1.9749587
A29: 26 | B29: Dorf | C29: 658 | D29: 4.1139241 | E29: 118.34532 | F29: 9.8784195 | G29: 21.580547 | H29: 61.702128 | I29: 16.717325 | J29: 7.5987842 | K29: 1.5197568 | L29: 7.5987842 | M29: 10.638298 | N29: 258 | O29: 2.5387597 | P29: 5.56 | Q29: 12.454874 | R29: 52 | S29: 46.389892 | T29: -53 | U29: 40.974729 | V29: 0.18050542 | W29: 129 | X29: 27 | Y29: 19 | Z29: 83 | AA29: 51 | AB29: 11 | AC29: 7 | AD29: 33 | AE29: 2.0689655 | AF29: 0 | AG29: X | AH29: 9.7357268 | AI29: 2.044378 | AJ29: 9.8479182 | AK29: 48.86562 | AL29: 4.350536 | AM29: 11.119422 | AN29: 0.81027175 | AO29: 0.062328596 | AP29: 3.9391673 | AQ29: 8.4392919
A30: 27 | B30: Feuerthalen | C30: 3614 | D30: 3.5530086 | E30: 1457.2581 | F30: 22.495849 | G30: 20.226895 | H30: 62.091865 | I30: 17.68124 | J30: 5.8035097 | K30: 1.381788 | L30: 12.71245 | M30: 7.1852978 | N30: 1626 | O30: 2.1906519 | P30: 2.48 | Q30: 42.8 | R30: 14 | S30: 11.2 | T30: -16 | U30: 44 | V30: 2 | W30: 1165 | X30: 5 | Y30: 277 | Z30: 883 | AA30: X | AB30: X | AC30: 33 | AD30: 161 | AE30: 2.2676991 | AF30: 4.669047 | AG30: 2.57 | AH30: 9.1272528 | AI30: 5.2455105 | AJ30: 18.651062 | AK30: 31.524648 | AL30: 3.2659509 | AM30: 14.340523 | AN30: 2.3084115 | AO30: 0.087049038 | AP30: 11.890254 | AQ30: 1.8183577
A31: 28 | B31: Flaach | C31: 1420 | D31: 15.729421 | E31: 139.62635 | F31: 15.422535 | G31: 21.197183 | H31: 61.619718 | I31: 17.183099 | J31: 0.7057163 | K31: 2.1171489 | L31: 10.585745 | M31: 8.4685956 | N31: 592 | O31: 2.3783784 | P31: 10.17 | Q31: 8.3333333 | R31: 10 | S31: 50.882353 | T31: -15 | U31: 33.72549 | V31: 7.0588235 | W31: 809 | X31: 153 | Y31: 146 | Z31: 510 | AA31: 138 | AB31: 27 | AC31: 24 | AD31: 87 | AE31: 4.2232278 | AF31: 5.0359712 | AG31: X | AH31: 9.9090109 | AI31: 1.6201937 | AJ31: 8.9286763 | AK31: 48.300558 | AL31: 6.4631641 | AM31: 8.5177576 | AN31: 0.77487526 | AO31: 0.029351335 | AP31: 9.1165248 | AQ31: 5.2069269
A32: 29 | B32: Flurlingen | C32: 1477 | D32: 3.4313725 | E32: 612.86307 | F32: 14.218009 | G32: 20.514557 | H32: 61.746784 | I32: 17.738659 | J32: 6.8610635 | K32: 2.058319 | L32: 12.349914 | M32: 7.5471698 | N32: 633 | O32: 2.314376 | P32: 2.41 | Q32: 22.821577 | R32: 14 | S32: 17.012448 | T32: -16 | U32: 56.431535 | V32: 3.7344398 | W32: X | X32: X | Y32: 128 | Z32: 308 | AA32: X | AB32: X | AC32: 18 | AD32: 83 | AE32: 1.4430014 | AF32: 7.6388889 | AG32: 0.9 | AH32: 15.358514 | AI32: 5.0175224 | AJ32: 16.660177 | AK32: 25.126551 | AL32: 2.0248095 | AM32: 14.529677 | AN32: 2.1249374 | AO32: 0.30594649 | AP32: 15.263948 | AQ32: 0.82883685
A33: 30 | B33: Andelfingen | C33: 2247 | D33: 20.806452 | E33: 333.38279 | F33: 13.351135 | G33: 23.40899 | H33: 57.231865 | I33: 19.359146 | J33: 1.792918 | K33: 2.689377 | L33: 8.9645899 | M33: 5.3787539 | N33: 919 | O33: 2.4156692 | P33: 6.74 | Q33: 15.820896 | R33: 18 | S33: 45.970149 | T33: -15 | U33: 32.985075 | V33: 5.2238806 | W33: 1551 | X33: 56 | Y33: 672 | Z33: 823 | AA33: 195 | AB33: 13 | AC33: 34 | AD33: 148 | AE33: 0.68965517 | AF33: 0 | AG33: 2.12 | AH33: 15.416526 | AI33: 2.7352445 | AJ33: 10.600337 | AK33: 31.217538 | AL33: 5.6762226 | AM33: 14.873524 | AN33: 3.9865093 | AO33: 0.0067453626 | AP33: 11.908938 | AQ33: 2.3642496
A34: 31 | B34: Henggart | C34: 2234 | D34: 0.94893809 | E34: 737.29373 | F34: 9.042077 | G34: 22.515667 | H34: 56.803939 | I34: 20.680394 | J34: 3.5770177 | K34: 1.3413816 | L34: 8.0482897 | M34: 6.7069081 | N34: 903 | O34: 2.4606866 | P34: 3.03 | Q34: 23.026316 | R34: 28 | S34: 56.25 | T34: -32 | U34: 19.736842 | V34: 0.98684211 | W34: 631 | X34: 33 | Y34: 326 | Z34: 272 | AA34: 112 | AB34: 13 | AC34: 15 | AD34: 84 | AE34: 0.91930541 | AF34: 0 | AG34: 2.01 | AH34: 11.906825 | AI34: 3.4143298 | AJ34: 9.1580297 | AK34: 37.297653 | AL34: 7.709106 | AM34: 13.660785 | AN34: 2.381365 | AO34: 0.093590766 | AP34: 10.028077 | AQ34: 3.4905889
A35: 32 | B35: Humlikon | C35: 485 | D35: 6.1269147 | E35: 131.79348 | F35: 8.2474227 | G35: 23.917526 | H35: 55.257732 | I35: 20.824742 | J35: 0 | K35: 0 | L35: 6.1728395 | M35: 16.460905 | N35: 187 | O35: 2.5828877 | P35: 3.68 | Q35: 9.5108696 | R35: 11 | S35: 62.5 | T35: -10 | U35: 27.717391 | V35: 0.27173913 | W35: 149 | X35: 22 | Y35: 15 | Z35: 112 | AA35: 40 | AB35: 8 | AC35: 8 | AD35: 24 | AE35: 2.0618557 | AF35: 0 | AG35: 1.44 | AH35: 15.946029 | AI35: 4.492487 | AJ35: 6.6084023 | AK35: 48.390064 | AL35: 4.0325054 | AM35: 10.027599 | AN35: 0.39865072 | AO35: 0 | AP35: 4.6458142 | AQ35: 4.2624962
A36: 33 | B36: Kleinandelfingen | C36: 2074 | D36: -0.52757794 | E36: 201.55491 | F36: 12.19865 | G36: 21.552555 | H36: 60.173578 | I36: 18.273867 | J36: 5.2593832 | K36: 2.3906287 | L36: 5.2593832 | M36: 6.6937605 | N36: 882 | O36: 2.3344671 | P36: 10.29 | Q36: 13.216715 | R36: 26 | S36: 50.242954 | T36: -26 | U36: 32.750243 | V36: 3.7900875 | W36: 1083 | X36: 57 | Y36: 479 | Z36: 547 | AA36: 189 | AB36: 26 | AC36: 36 | AD36: 127 | AE36: 3.2325339 | AF36: 0.96339114 | AG36: 1.99 | AH36: 12.906769 | AI36: 2.3633257 | AJ36: 10.368532 | AK36: 40.115522 | AL36: 4.1083632 | AM36: 12.744061 | AN36: 3.2256752 | AO36: 0.024406118 | AP36: 10.624797 | AQ36: 2.0216401
A37: 34 | B37: Laufen-Uhwiesen | C37: 1761 | D37: 16.545334 | E37: 280.41401 | F37: 13.798978 | G37: 19.363998 | H37: 59.398069 | I37: 21.237933 | J37: 2.8818444 | K37: 0.57636888 | L37: 5.1873199 | M37: 4.610951 | N37: 781 | O37: 2.2317542 | P37: 6.28 | Q37: 12.400636 | R37: 10 | S37: 39.586645 | T37: -11 | U37: 44.515103 | V37: 3.4976153 | W37: 472 | X37: 76 | Y37: 176 | Z37: 220 | AA37: 105 | AB37: 21 | AC37: 16 | AD37: 68 | AE37: 1.3714286 | AF37: 26.978417 | AG37: 1.93 | AH37: 16.287552 | AI37: 5.0628659 | AJ37: 9.0699683 | AK37: 36.860543 | AL37: 2.0539399 | AM37: 12.424417 | AN37: 2.7689797 | AO37: 0.35512045 | AP37: 10.04415 | AQ37: 3.0521163
A38: 35 | B38: Marthalen | C38: 1918 | D38: -0.67322631 | E38: 135.73956 | F38: 11.366006 | G38: 19.812304 | H38: 60.84463 | I38: 19.343066 | J38: 5.2273915 | K38: 3.1364349 | L38: 8.8865656 | M38: 5.7501307 | N38: 839 | O38: 2.2562574 | P38: 14.13 | Q38: 11.80212 | R38: 34 | S38: 47.279152 | T38: -36 | U38: 39.151943 | V38: 1.7667845 | W38: 1164 | X38: 92 | Y38: 276 | Z38: 796 | AA38: 206 | AB38: 32 | AC38: 49 | AD38: 125 | AE38: 0.87336245 | AF38: 1.0219724 | AG38: 1.05 | AH38: 7.7296772 | AI38: 1.989996 | AJ38: 9.8672136 | AK38: 49.623952 | AL38: 2.2814783 | AM38: 9.8996006 | AN38: 3.9224153 | AO38: 0.25549678 | AP38: 11.198676 | AQ38: 2.3966318
A39: 37 | B39: Ossingen | C39: 1668 | D39: 23.738872 | E39: 127.42552 | F39: 11.7506 | G39: 20.863309 | H39: 61.570743 | I39: 17.565947 | J39: 3.6264733 | K39: 3.022061 | L39: 7.8573587 | M39: 4.2308855 | N39: 710 | O39: 2.3253521 | P39: 13.09 | Q39: 9.3200917 | R39: 18 | S39: 56.455309 | T39: -20 | U39: 29.106188 | V39: 5.118411 | W39: 426 | X39: 69 | Y39: 53 | Z39: 304 | AA39: 106 | AB39: 26 | AC39: 16 | AD39: 64 | AE39: 1.8018018 | AF39: 27.44097 | AG39: 2.13 | AH39: 12.159123 | AI39: 3.1299784 | AJ39: 10.453566 | AK39: 40.563209 | AL39: 5.8616812 | AM39: 11.596851 | AN39: 2.6051916 | AO39: 0.009371193 | AP39: 9.7928966 | AQ39: 1.7102427
A40: 38 | B40: Rheinau | C40: 1316 | D40: 1.0752688 | E40: 147.36842 | F40: 19.680851 | G40: 17.857143 | H40: 61.550152 | I40: 20.592705 | J40: 5.2850132 | K40: 0 | L40: 6.0400151 | M40: 11.325028 | N40: 588 | O40: 2.1904762 | P40: 8.93 | Q40: 11.646137 | R40: 16 | S40: 26.203807 | T40: -18 | U40: 54.871221 | V40: 7.2788354 | W40: 694 | X40: 15 | Y40: 50 | Z40: 629 | AA40: X | AB40: X | AC40: 18 | AD40: 74 | AE40: 2.1961933 | AF40: 6.1585835 | AG40: 1.43 | AH40: 6.0090352 | AI40: 8.2059533 | AJ40: 21.146111 | AK40: 33.009468 | AL40: 1.3862244 | AM40: 10.718485 | AN40: 2.1845411 | AO40: 0.6931122 | AP40: 12.841141 | AQ40: 1.788477
A41: 39 | B41: Thalheim an der Thur | C41: 938 | D41: 14.669927 | E41: 145.65217 | F41: 9.5948827 | G41: 23.240938 | H41: 60.447761 | I41: 16.311301 | J41: 2.1563342 | K41: 3.2345013 | L41: 12.938005 | M41: 5.3908356 | N41: 383 | O41: 2.4255875 | P41: 6.44 | Q41: 8.9922481 | R41: 6 | S41: 65.581395 | T41: -6 | U41: 21.24031 | V41: 4.1860465 | W41: 256 | X41: 52 | Y41: 72 | Z41: 132 | AA41: 70 | AB41: 18 | AC41: 8 | AD41: 44 | AE41: 0.97323601 | AF41: 0 | AG41: 2.07 | AH41: 10.734877 | AI41: 1.7296605 | AJ41: 7.7971996 | AK41: 54.690217 | AL41: 3.6972637 | AM41: 6.35124 | AN41: 2.0774229 | AO41: 0.0091516427 | AP41: 9.2614624 | AQ41: 2.2421525
A42: 40 | B42: Trüllikon | C42: 1061 | D42: 6.8479355 | E42: 110.98326 | F42: 8.1998115 | G42: 19.604147 | H42: 56.550424 | I42: 23.845429 | J42: 5.6417489 | K42: 1.880583 | L42: 6.5820404 | M42: 9.4029149 | N42: 467 | O42: 2.2655246 | P42: 9.56 | Q42: 8.6820084 | R42: 15 | S42: 61.715481 | T42: -18 | U42: 29.288703 | V42: 0.31380753 | W42: 309 | X42: 91 | Y42: 89 | Z42: 129 | AA42: 94 | AB42: 31 | AC42: 17 | AD42: 46 | AE42: 0.96525097 | AF42: 0.94428706 | AG42: X | AH42: 6.0110081 | AI42: 2.0640209 | AJ42: 8.1764195 | AK42: 49.20336 | AL42: 2.3754345 | AM42: 10.059386 | AN42: 6.9887022 | AO42: 0.2679606 | AP42: 10.530127 | AQ42: 3.6066049
A43: 41 | B43: Truttikon | C43: 463 | D43: -2.5263158 | E43: 104.98866 | F43: 4.9676026 | G43: 21.814255 | H43: 59.827214 | I43: 18.358531 | J43: 0 | K43: 2.1276596 | L43: 4.2553191 | M43: 6.3829787 | N43: 182 | O43: 2.510989 | P43: 4.41 | Q43: 6.3636364 | R43: 2 | S43: 64.545455 | T43: -2 | U43: 28.636364 | V43: 0.45454545 | W43: 117 | X43: 53 | Y43: 25 | Z43: 39 | AA43: 36 | AB43: 17 | AC43: 5 | AD43: 14 | AE43: 0.49751244 | AF43: 2.0920502 | AG43: 1.26 | AH43: 9.3949694 | AI43: 1.0061183 | AJ43: 13.446635 | AK43: 42.447315 | AL43: 5.5880354 | AM43: 4.5683209 | AN43: 2.0802175 | AO43: 0.99252209 | AP43: 9.9660095 | AQ43: 8.4976207
A44: 43 | B44: Volken | C44: 380 | D44: 22.580645 | E44: 118.75 | F44: 9.4736842 | G44: 27.631579 | H44: 61.052632 | I44: 11.315789 | J44: 0 | K44: 2.6954178 | L44: 8.0862534 | M44: 5.3908356 | N44: 155 | O44: 2.4258065 | P44: 3.2 | Q44: 6.097561 | R44: 3 | S44: 64.634146 | T44: -3 | U44: 29.268293 | V44: 0 | W44: 103 | X44: 27 | Y44: 13 | Z44: 63 | AA44: 31 | AB44: 11 | AC44: 5 | AD44: 15 | AE44: 0.62111801 | AF44: 26.315789 | AG44: X | AH44: 11.878814 | AI44: 0.80645161 | AJ44: 5.7759372 | AK44: 49.956408 | AL44: 7.5414124 | AM44: 11.159547 | AN44: 0.28334786 | AO44: 0 | AP44: 8.5222319 | AQ44: 2.5937228
...

Sheet data_for_import
A1: bfs_number | B1: bfs_name | C1: pop | D1: pop_dens | E1: frg_pct | F1: emp | G1: mean_taxable_income
A2: 1 | B2: Aeugst am Albis | C2: 1981 | D2: 250.44248 | E2: 14.184755 | F2: 442 | G2: =VLOOKUP(A2,fiscal!$A$1:$D$2198,4,FALSE) -> 115285.71
A3: 2 | B3: Affoltern am Albis | C3: 12303 | D3: 1161.7564 | E3: 28.700317 | F3: 6920 | G3: =VLOOKUP(A3,fiscal!$A$1:$D$2198,4,FALSE) -> 74896.29
A4: 3 | B4: Bonstetten | C4: 5572 | D4: 749.93271 | E4: 16.564968 | F4: 1014 | G4: =VLOOKUP(A4,fiscal!$A$1:$D$2198,4,FALSE) -> 91023.214
A5: 4 | B5: Hausen am Albis | C5: 3751 | D5: 275.80882 | E5: 16.022394 | F5: 1021 | G5: =VLOOKUP(A5,fiscal!$A$1:$D$2198,4,FALSE) -> 97382.179
A6: 5 | B6: Hedingen | C6: 3778 | D6: 578.56049 | E6: 16.410799 | F6: 1478 | G6: =VLOOKUP(A6,fiscal!$A$1:$D$2198,4,FALSE) -> 94955.074
A7: 6 | B7: Kappel am Albis | C7: 1221 | D7: 154.16667 | E7: 17.526618 | F7: 319 | G7: =VLOOKUP(A7,fiscal!$A$1:$D$2198,4,FALSE) -> 97089.858
A8: 7 | B8: Knonau | C8: 2378 | D8: 367.5425 | E8: 18.292683 | F8: 566 | G8: =VLOOKUP(A8,fiscal!$A$1:$D$2198,4,FALSE) -> 86992.469
A9: 8 | B9: Maschwanden | C9: 645 | D9: 137.52665 | E9: 12.868217 | F9: 175 | G9: =VLOOKUP(A9,fiscal!$A$1:$D$2198,4,FALSE) -> 72426.756
A10: 9 | B10: Mettmenstetten | C10: 5200 | D10: 399.07905 | E10: 14.769231 | F10: 1680 | G10: =VLOOKUP(A10,fiscal!$A$1:$D$2198,4,FALSE) -> 90336.051
A11: 10 | B11: Obfelden | C11: 5721 | D11: 758.75332 | E11: 21.464779 | F11: 1252 | G11: =VLOOKUP(A11,fiscal!$A$1:$D$2198,4,FALSE) -> 79419.346
A12: 11 | B12: Ottenbach | C12: 2588 | D12: 515.53785 | E12: 13.137558 | F12: 683 | G12: =VLOOKUP(A12,fiscal!$A$1:$D$2198,4,FALSE) -> 83296.276
A13: 12 | B13: Rifferswil | C13: 1129 | D13: 173.4255 | E13: 10.717449 | F13: 250 | G13: =VLOOKUP(A13,fiscal!$A$1:$D$2198,4,FALSE) -> 96300.208
... A23: 28 | B23: Flaach | C23: 1420 | D23: 139.62635 | E23: 15.422535 | F23: 809 | G23: =VLOOKUP(A23,fiscal!$A$1:$D$2198,4,FALSE) -> 74880.526
A24: 29 | B24: Flurlingen | C24: 1477 | D24: 612.86307 | E24: 14.218009 | G24: =VLOOKUP(A24,fiscal!$A$1:$D$2198,4,FALSE) -> 95652.288
A25: 30 | B25: Andelfingen | C25: 2247 | D25: 333.38279 | E25: 13.351135 | F25: 1551 | G25: =VLOOKUP(A25,fiscal!$A$1:$D$2198,4,FALSE) -> 85483.041
A26: 31 | B26: Henggart | C26: 2234 | D26: 737.29373 | E26: 9.042077 | F26: 631 | G26: =VLOOKUP(A26,fiscal!$A$1:$D$2198,4,FALSE) -> 79746.332
A27: 32 | B27: Humlikon | C27: 485 | D27: 131.79348 | E27: 8.2474227 | F27: 149 | G27: =VLOOKUP(A27,fiscal!$A$1:$D$2198,4,FALSE) -> 92520.488
A28: 33 | B28: Kleinandelfingen | C28: 2074 | D28: 201.55491 | E28: 12.19865 | F28: 1083 | G28: =VLOOKUP(A28,fiscal!$A$1:$D$2198,4,FALSE) -> 79336.957
A29: 34 | B29: Laufen-Uhwiesen | C29: 1761 | D29: 280.41401 | E29: 13.798978 | F29: 472 | G29: =VLOOKUP(A29,fiscal!$A$1:$D$2198,4,FALSE) -> 98692.036
A30: 35 | B30: Marthalen | C30: 1918 | D30: 135.73956 | E30: 11.366006 | F30: 1164 | G30: =VLOOKUP(A30,fiscal!$A$1:$D$2198,4,FALSE) -> 81878.308
A31: 37 | B31: Ossingen | C31: 1668 | D31: 127.42552 | E31: 11.7506 | F31: 426 | G31: =VLOOKUP(A31,fiscal!$A$1:$D$2198,4,FALSE) -> 74357.755
A32: 38 | B32: Rheinau | C32: 1316 | D32: 147.36842 | E32: 19.680851 | F32: 694 | G32: =VLOOKUP(A32,fiscal!$A$1:$D$2198,4,FALSE) -> 72849.486
A33: 39 | B33: Thalheim an der Thur | C33: 938 | D33: 145.65217 | E33: 9.5948827 | F33: 256 | G33: =VLOOKUP(A33,fiscal!$A$1:$D$2198,4,FALSE) -> 76950.455
A34: 40 | B34: Trüllikon | C34: 1061 | D34: 110.98326 | E34: 8.1998115 | F34: 309 | G34: =VLOOKUP(A34,fiscal!$A$1:$D$2198,4,FALSE) -> 73012.851
A35: 41 | B35: Truttikon | C35: 463 | D35: 104.98866 | E35: 4.9676026 | F35: 117 | G35: =VLOOKUP(A35,fiscal!$A$1:$D$2198,4,FALSE) -> 78396.939
A36: 43 | B36: Volken | C36: 380 | D36: 118.75 | E36: 9.4736842 | F36: 103 | G36: =VLOOKUP(A36,fiscal!$A$1:$D$2198,4,FALSE) -> 87196.364
... A94: 136 | B94: Langnau am Albis | C94: 7727 | D94: 891.23414 | E94: 27.785687 | F94: 1533 | G94: =VLOOKUP(A94,fiscal!$A$1:$D$2198,4,FALSE) -> 97894.616
A95: 137 | B95: Oberrieden | C95: 5002 | D95: 1792.8315 | E95: 21.291483 | G95: =VLOOKUP(A95,fiscal!$A$1:$D$2198,4,FALSE) -> 121367.88
A96: 138 | B96: Richterswil | C96: 13632 | D96: 1810.3586 | E96: 19.476232 | F96: 4293 | G96: =VLOOKUP(A96,fiscal!$A$1:$D$2198,4,FALSE) -> 90808.769
A97: 139 | B97: Rüschlikon | C97: 6092 | D97: 2079.1809 | E97: 33.650689 | F97: 3050 | G97: =VLOOKUP(A97,fiscal!$A$1:$D$2198,4,FALSE) -> 189266.74
A98: 141 | B98: Thalwil | C98: 18139 | D98: 3298 | E98: 29.031369 | F98: 6582 | G98: =VLOOKUP(A98,fiscal!$A$1:$D$2198,4,FALSE) -> 117599.52
A99: 151 | B99: Erlenbach (ZH) | C99: 5592 | D99: 1934.9481 | E99: 22.961373 | F99: 1934 | G99: =VLOOKUP(A99,fiscal!$A$1:$D$2198,4,FALSE) -> 195853.37
A100: 152 | B100: Herrliberg | C100: 6460 | D100: 718.5762 | E100: 22.44582 | F100: 1413 | G100: =VLOOKUP(A100,fiscal!$A$1:$D$2198,4,FALSE) -> 192037.67
A101: 153 | B101: Hombrechtikon | C101: 8775 | D101: 720.44335 | E101: 20.672365 | F101: 2910 | G101: =VLOOKUP(A101,fiscal!$A$1:$D$2198,4,FALSE) -> 80004.68
A102: 154 | B102: Küsnacht (ZH) | C102: 14564 | D102: 1178.3172 | E102: 26.503708 | F102: 6401 | G102: =VLOOKUP(A102,fiscal!$A$1:$D$2198,4,FALSE) -> 191913.14
A103: 155 | B103: Männedorf | C103: 11359 | D103: 2381.3417 | E103: 20.380315 | F103: 4984 | G103: =VLOOKUP(A103,fiscal!$A$1:$D$2198,4,FALSE) -> 107425.35
A104: 156 | B104: Meilen | C104: 14335 | D104: 1200.5863 | E104: 23.188001 | F104: 5910 | G104: =VLOOKUP(A104,fiscal!$A$1:$D$2198,4,FALSE) -> 143986.01
A105: 157 | B105: Oetwil am See | C105: 4840 | D105: 792.14403 | E105: 29.256198 | F105: 2303 | G105: =VLOOKUP(A105,fiscal!$A$1:$D$2198,4,FALSE) -> 71492.379
A106: 158 | B106: Stäfa | C106: 14718 | D106: 1713.3877 | E106: 19.323278 | F106: 6193 | G106: =VLOOKUP(A106,fiscal!$A$1:$D$2198,4,FALSE) -> 104308.45
...

Sheet fiscal
A1: 1 | B1: Aeugst am Albis | C1: 110.559 | D1: 115285.71
A2: 2 | B2: Affoltern am Albis | C2: 411.7798 | D2: 74896.29
A3: 3 | B3: Bonstetten | C3: 230.5618 | D3: 91023.214
A4: 4 | B4: Hausen am Albis | C4: 164.4785 | D4: 97382.179
A5: 5 | B5: Hedingen | C5: 166.5512 | D5: 94955.074
A6: 6 | B6: Kappel am Albis | C6: 54.5645 | D6: 97089.858
A7: 7 | B7: Knonau | C7: 91.2551 | D7: 86992.469
A8: 8 | B8: Maschwanden | C8: 21.6556 | D8: 72426.756
A9: 9 | B9: Mettmenstetten | C9: 220.5103 | D9: 90336.051
A10: 10 | B10: Obfelden | C10: 194.1803 | D10: 79419.346
A11: 11 | B11: Ottenbach | C11: 107.3689 | D11: 83296.276
A12: 12 | B12: Rifferswil | C12: 46.3204 | D12: 96300.208
... A177: 324 | B177: Bleienbach | C177: 19.4166 | D177: 58660.423
A178: 325 | B178: Busswil bei Melchnau | C178: X | D178: X
A179: 326 | B179: Gondiswil | C179: 16.2679 | D179: 55332.993
A180: 329 | B180: Langenthal | C180: 454.2146 | D180: 66444.5
A181: 331 | B181: Lotzwil | C181: 69.9807 | D181: 62988.929
A182: 332 | B182: Madiswil | C182: 88.5429 | D182: 60645.822
A183: 333 | B183: Melchnau | C183: 37.9866 | D183: 59633.595
A184: 334 | B184: Obersteckholz | C184: 11.6515 | D184: 60684.896
A185: 335 | B185: Oeschenbach | C185: X | D185: X
A186: 336 | B186: Reisiswil | C186: X | D186: X
A187: 337 | B187: Roggwil (BE) | C187: 107.2196 | D187: 61408.706
A188: 338 | B188: Rohrbach | C188: 36.4339 | D188: 53816.691
A189: 339 | B189: Rohrbachgraben | C189: X | D189: X
A190: 340 | B190: Rütschelen | C190: 13.0628 | D190: 58316.071
A191: 341 | B191: Schwarzhäusern | C191: 16.2226 | D191: 69925
A192: 342 | B192: Thunstetten | C192: 96.4356 | D192: 64721.879
A193: 344 | B193: Ursenbach | C193: 20.9775 | D193: 56089.572
A194: 345 | B194: Wynau | C194: 41.573 | D194: 61864.583
A195: 351 | B195: Bern | C195: 4902.4168 | D195: 72779.347
A196: 352 | B196: Bolligen | C196: 265.8618 | D196: 91708.106
A197: 353 | B197: Bremgarten bei Bern | C197: 190.5093 | D197: 93616.364
A198: 354 | B198: Kirchlindach | C198: 142.8866 | D198: 89584.075
A199: 355 | B199: Köniz | C199: 1473.5628 | D199: 75609.975
A200: 356 | B200: Muri bei Bern | C200: 652.6368 | D200: 107465.31
A201: 357 | B201: Oberbalm | C201: 24.2867 | D201: 63744.619
... A216: 388 | B216: Leuzigen | C216: 35.106 | D216: 63368.231
A217: 389 | B217: Meienried | C217: X | D217: X
A218: 390 | B218: Meinisberg | C218: 38.2566 | D218: 67830.851
...
